Workbook

Sheet Página1
A1: Estado | B1: Pos. | C1: Cidade | D1: Pop. (Censo2010)[1] | E1: Pop. (Estim. 2019)[2] | F1: % de População | G1: Área (km²) | H1: Microrregião | I1: Mesorregião | J1: Visitado | K1: Igreja visitada | L1: Postado Face
A2: =_xludf.CONCAT(C2," (RS)") -> #NAME? | B2: 270 | C2: Aceguá | D2: 4394 | E2: 4858 | F2: =E2/$E$504 -> 0.00042659954 | G2: 1551.339 | H2: Campanha Meridional | I2: Sudoeste | L2: Não | M2: Total | N2: 497
A3: =_xludf.CONCAT(C3," (RS)") -> #NAME? | B3: 324 | C3: Água Santa | D3: 3726 | E3: 3753 | F3: =E3/$E$504 -> 0.00032956527 | G3: 291.503 | H3: Passo Fundo | I3: Noroeste | J3: 44027 | K3: Igreja Santo Antônio | L3: Sim | M3: Visitados | N3: =497-COUNTIF(J2:J503,"") -> 316 | O3: =N3/$N$2 -> 0.63581489
A4: =_xludf.CONCAT(C4," (RS)") -> #NAME? | B4: 117 | C4: Agudo | D4: 16729 | E4: 16461 | F4: =E4/$E$504 -> 0.0014455033 | G4: 534.624 | H4: Restinga Seca | I4: Centro Ocidental | J4: 45532 | K4: São Bonifácio | L4: Não | M4: Faltam | N4: =497-N3 -> 181
A5: =_xludf.CONCAT(C5," (RS)") -> #NAME? | B5: 204 | C5: Ajuricaba | D5: 7255 | E5: 7024 | F5: =E5/$E$504 -> 0.00061680428 | G5: 322.699 | H5: Ijuí | I5: Noroeste | L5: Não | M5: Postados no Face | N5: =COUNTIF(L:L,"Sim") -> 70 | O5: =N5/$N$2 -> 0.14084507
A6: =_xludf.CONCAT(C6," (RS)") -> #NAME? | B6: 239 | C6: Alecrim | D6: 7045 | E6: 5950 | F6: =E6/$E$504 -> 0.00052249224 | G6: 316.394 | H6: Santa Rosa | I6: Noroeste | L6: Não
A7: =_xludf.CONCAT(C7," (RS)") -> #NAME? | B7: 28 | C7: Alegrete | D7: 77673 | E7: 73589 | F7: =E7/$E$504 -> 0.0064621313 | G7: 7800.163 | H7: Campanha Ocidental | I7: Sudoeste | L7: Não
A8: =_xludf.CONCAT(C8," (RS)") -> #NAME? | B8: 333 | C8: Alegria | D8: 4301 | E8: 3559 | F8: =E8/$E$504 -> 0.00031252939 | G8: 172.794 | H8: Ijuí | I8: Noroeste | L8: Não
A9: =_xludf.CONCAT(C9," (RS)") -> #NAME? | B9: 462 | C9: Almirante Tamandaré do Sul | D9: 2062 | E9: 1979 | F9: =E9/$E$504 -> 0.00017378355 | G9: 265.327 | H9: Carazinho | I9: Noroeste | J9: 46180 | K9: São João Batista | L9: Não
A10: =_xludf.CONCAT(C10," (RS)") -> #NAME? | B10: 229 | C10: Alpestre | D10: 8027 | E10: 6258 | F10: =E10/$E$504 -> 0.00054953889 | G10: 325.979 | H10: Frederico Westphalen | I10: Noroeste | J10: 46178 | K10: São Francisco | L10: Não
A11: =_xludf.CONCAT(C11," (RS)") -> #NAME? | B11: 482 | C11: Alto Alegre | D11: 1848 | E11: 1663 | F11: =E11/$E$504 -> 0.00014603438 | G11: 115.335 | H11: Cruz Alta | I11: Noroeste | L11: Não
A12: =_xludf.CONCAT(C12," (RS)") -> #NAME? | B12: 364 | C12: Alto Feliz | D12: 2908 | E12: 3020 | F12: =E12/$E$504 -> 0.00026519774 | G12: 78.846 | H12: Montenegro | I12: Metropolitana | J12: 43984 | K12: Igreja Santo Inácio da Feliz | L12: Não
A13: =_xludf.CONCAT(C13," (RS)") -> #NAME? | B13: 11 | C13: Alvorada | D13: 195718 | E13: 210305 | F13: =E13/$E$504 -> 0.018467686 | G13: 71.648 | H13: Porto Alegre | I13: Metropolitana | J13: 43998 | K13: Igreja Santo Antônio | L13: Sim
A14: =_xludf.CONCAT(C14," (RS)") -> #NAME? | B14: 203 | C14: Amaral Ferrador | D14: 6355 | E14: 7031 | F14: =E14/$E$504 -> 0.00061741898 | G14: 505.983 | H14: Serras de Sudeste | I14: Sudeste | L14: Não
A15: =_xludf.CONCAT(C15," (RS)") -> #NAME? | B15: 197 | C15: Ametista do Sul | D15: 7323 | E15: 7409 | F15: =E15/$E$504 -> 0.0006506126 | G15: 93.704 | H15: Frederico Westphalen | I15: Noroeste | J15: 44845 | K15: São Miguel Arcanjo | L15: VISITAMOS NOVAMENTE EM 05/06/2024
A16: =_xludf.CONCAT(C16," (RS)") -> #NAME? | B16: 495 | C16: André da Rocha | D16: 1216 | E16: 1324 | F16: =E16/$E$504 -> 0.0001162655 | G16: 331.227 | H16: Guaporé | I16: Nordeste | J16: 44015 | K16: Igreja São Sebastião | L16: Não
A17: =_xludf.CONCAT(C17," (RS)") -> #NAME? | B17: 237 | C17: Anta Gorda | D17: 6073 | E17: 5981 | F17: =E17/$E$504 -> 0.00052521447 | G17: 242.26 | H17: Guaporé | I17: Nordeste | J17: 44026 | K17: Igreja São Carlos | L17: Sim
A18: =_xludf.CONCAT(C18," (RS)") -> #NAME? | B18: 139 | C18: Antônio Prado | D18: 12837 | E18: 13050 | F18: =E18/$E$504 -> 0.0011459704 | G18: 348.191 | H18: Caxias do Sul | I18: Nordeste | J18: 44015 | K18: Igreja Sagrado Coração de Jesus | L18: Não
A19: =_xludf.CONCAT(C19," (RS)") -> #NAME? | B19: 329 | C19: Arambaré | D19: 3693 | E19: 3600 | F19: =E19/$E$504 -> 0.00031612976 | G19: 518.193 | H19: Camaquã | I19: Metropolitana | J19: 44196 | K19: Igreja Nossa Senhora dos Navegantes | L19: Sim
A20: =_xludf.CONCAT(C20," (RS)") -> #NAME? | B20: 247 | C20: Araricá | D20: 4868 | E20: 5698 | F20: =E20/$E$504 -> 0.00050036315 | G20: 35.296 | H20: Porto Alegre | I20: Metropolitana | J20: 43965 | K20: Igreja Nossa Senhora da Conceição | L20: Sim
A21: =_xludf.CONCAT(C21," (RS)") -> #NAME? | B21: 231 | C21: Aratiba | D21: 6568 | E21: 6235 | F21: =E21/$E$504 -> 0.00054751918 | G21: 342.279 | H21: Erechim | I21: Noroeste | J21: 46178 | K21: São Tiago | L21: Não
A22: =_xludf.CONCAT(C22," (RS)") -> #NAME? | B22: 107 | C22: Arroio do Meio | D22: 18783 | E22: 20805 | F22: =E22/$E$504 -> 0.0018269666 | G22: 157.58 | H22: Lajeado-Estrela | I22: Centro Oriental | J22: 44389 | K22: Igreja Nossa Senhora do Perpétuo Socorro | L22: Não
A23: =_xludf.CONCAT(C23," (RS)") -> #NAME? | B23: 376 | C23: Arroio do Padre | D23: 2730 | E23: 2921 | F23: =E23/$E$504 -> 0.00025650417 | G23: 124.693 | H23: Pelotas | I23: Sudeste | L23: Não
A24: =_xludf.CONCAT(C24," (RS)") -> #NAME? | B24: 167 | C24: Arroio do Sal | D24: 7744 | E24: 10065 | F24: =E24/$E$504 -> 0.00088384611 | G24: 119.163 | H24: Osório | I24: Metropolitana | J24: 43999 | K24: Igreja Nossa Senhora de Lourdes | L24: Sim
A25: =_xludf.CONCAT(C25," (RS)") -> #NAME? | B25: 138 | C25: Arroio do Tigre | D25: 12648 | E25: 13373 | F25: =E25/$E$504 -> 0.0011743342 | G25: 315.132 | H25: Santa Cruz do Sul | I25: Centro Oriental | L25: Não
A26: =_xludf.CONCAT(C26," (RS)") -> #NAME? | B26: 129 | C26: Arroio dos Ratos | D26: 13608 | E26: 14151 | F26: =E26/$E$504 -> 0.0012426534 | G26: 425.791 | H26: São Jerônimo | I26: Metropolitana | L26: Não
A27: =_xludf.CONCAT(C27," (RS)") -> #NAME? | B27: 113 | C27: Arroio Grande | D27: 18469 | E27: 18293 | F27: =E27/$E$504 -> 0.0016063782 | G27: 2508.545 | H27: Jaguarão | I27: Sudeste | J27: 43988 | K27: Igreja Nossa Senhora da Graça | L27: Não
A28: =_xludf.CONCAT(C28," (RS)") -> #NAME? | B28: 161 | C28: Arvorezinha | D28: 10229 | E28: 10424 | F28: =E28/$E$504 -> 0.00091537127 | G28: 270.241 | H28: Guaporé | I28: Nordeste | J28: 44026 | K28: Igreja São João Batista | L28: Não
A29: =_xludf.CONCAT(C29," (RS)") -> #NAME? | B29: 216 | C29: Augusto Pestana | D29: 7097 | E29: 6661 | F29: =E29/$E$504 -> 0.00058492786 | G29: 348.33 | H29: Ijuí | I29: Noroeste | L29: Não
A30: =_xludf.CONCAT(C30," (RS)") -> #NAME? | B30: 332 | C30: Áurea | D30: 3665 | E30: 3573 | F30: =E30/$E$504 -> 0.00031375878 | G30: 156.727 | H30: Erechim | I30: Noroeste | J30: 44391 | K30: Igreja Nossa Senhora do Monte Claro | L30: Não
A31: =_xludf.CONCAT(C31," (RS)") -> #NAME? | B31: 17 | C31: Bagé | D31: 116792 | E31: 121143 | F31: =E31/$E$504 -> 0.01063803 | G31: 4090.36 | H31: Campanha Meridional | I31: Sudoeste | L31: Não
A32: =_xludf.CONCAT(C32," (RS)") -> #NAME? | B32: 131 | C32: Balneário Pinhal | D32: 10855 | E32: 14068 | F32: =E32/$E$504 -> 0.0012353648 | G32: 102.386 | H32: Osório | I32: Metropolitana | J32: 43999 | K32: Igreja Santo Antônio de Pádua | L32: Não
A33: =_xludf.CONCAT(C33," (RS)") -> #NAME? | B33: 233 | C33: Barão | D33: 5742 | E33: 6171 | F33: =E33/$E$504 -> 0.00054189909 | G33: 124.113 | H33: Montenegro | I33: Metropolitana | J33: 43985 | K33: Igreja São José | L33: Sim
A34: =_xludf.CONCAT(C34," (RS)") -> #NAME? | B34: 218 | C34: Barão de Cotegipe | D34: 6529 | E34: 6623 | F34: =E34/$E$504 -> 0.00058159094 | G34: 260.505 | H34: Erechim | I34: Noroeste | L34: Não
A35: =_xludf.CONCAT(C35," (RS)") -> #NAME? | B35: 194 | C35: Barão do Triunfo | D35: 7018 | E35: 7487 | F35: =E35/$E$504 -> 0.00065746208 | G35: 436.101 | H35: São Jerônimo | I35: Metropolitana | L35: Não
A36: =_xludf.CONCAT(C36," (RS)") -> #NAME? | B36: 350 | C36: Barra do Guarita | D36: 3089 | E36: 3238 | F36: =E36/$E$504 -> 0.00028434115 | G36: 62.801 | H36: Três Passos | I36: Noroeste | L36: Não
A37: =_xludf.CONCAT(C37," (RS)") -> #NAME? | B37: 306 | C37: Barra do Quaraí | D37: 4016 | E37: 4202 | F37: =E37/$E$504 -> 0.00036899368 | G37: 1055.937 | H37: Campanha Ocidental | I37: Sudoeste | L37: Não
A38: =_xludf.CONCAT(C38," (RS)") -> #NAME? | B38: 135 | C38: Barra do Ribeiro | D38: 12568 | E38: 13491 | F38: =E38/$E$504 -> 0.0011846963 | G38: 729.316 | H38: Camaquã | I38: Metropolitana | J38: 43987 | K38: Igreja São José, | L38: Sim
A39: =_xludf.CONCAT(C39," (RS)") -> #NAME? | B39: 476 | C39: Barra do Rio Azul | D39: 2003 | E39: 1726 | F39: =E39/$E$504 -> 0.00015156666 | G39: 146.995 | H39: Erechim | I39: Noroeste | J39: 46178 | K39: Nossa Senhora Medianeira | L39: Não
A40: =_xludf.CONCAT(C40," (RS)") -> #NAME? | B40: 415 | C40: Barra Funda | D40: 2367 | E40: 2527 | F40: =E40/$E$504 -> 0.00022190553 | G40: 60.437 | H40: Carazinho | I40: Noroeste | L40: Não
...

Sheet Página6

Sheet Página3

Sheet Página2
A1: Posição | B1: Município | C1: Área (km²)[1] | D1: % do estado | H1: Microrregião | I1: area | J1: municipios | M1: Municípios | N1: População | O1: %
A2: 42 | B2: Aceguá | C2: 1551.339 | D2: 0.5507 | H2: Cachoeira do Sul | I2: =SUMIF(Página1!$H$2:$H$503,H2,Página1!$G$2:$G$503) -> 7582.185 | J2: =COUNTIF(Página1!$H$2:$H$503,H2) -> 7 | K2: Até | L2: 5000 | M2: =COUNTIF(Página1!$E$2:$E$503,"<="&L2) -> 231 | N2: =SUMIF(Página1!$E$2:$E$503,"<="&L2) -> 692742 | O2: =N2/Página1!$E$504 -> 0.060832322 | P2: =M2/497 -> 0.46478873
A3: 198 | B3: Água Santa | C3: 291.503 | D3: 0.1035 | H3: Camaquã | I3: =SUMIF(Página1!$H$2:$H$503,H3,Página1!$G$2:$G$503) -> 5664.363 | J3: =COUNTIF(Página1!$H$2:$H$503,H3) -> 8 | K3: Até | L3: 10000 | M3: =COUNTIFS(Página1!$E$2:$E$503,"<="&L3,Página1!$E$2:$E$503,">"&L2) -> 99 | N3: =SUMIFS(Página1!$E$2:$E$503,Página1!$E$2:E$503,"<="&L3,Página1!$E$2:$E$503,">"&L2) -> 672962 | O3: =N3/Página1!$E$504 -> 0.059095365 | P3: =M3/497 -> 0.19919517
A4: 114 | B4: Agudo | C4: 534.624 | D4: 0.1898 | H4: Campanha Central | I4: =SUMIF(Página1!$H$2:$H$503,H4,Página1!$G$2:$G$503) -> 17297.266 | J4: =COUNTIF(Página1!$H$2:$H$503,H4) -> 4 | K4: Até | L4: 15000 | M4: =COUNTIFS(Página1!$E$2:$E$503,"<="&L4,Página1!$E$2:$E$503,">"&L3) -> 41 | N4: =SUMIFS(Página1!$E$2:$E$503,Página1!$E$2:E$503,"<="&L4,Página1!$E$2:$E$503,">"&L3) -> 495650 | O4: =N4/Página1!$E$504 -> 0.043524921 | P4: =M4/497 -> 0.08249497
A5: 181 | B5: Ajuricaba | C5: 322.699 | D5: 0.1146 | H5: Campanha Meridional | I5: =SUMIF(Página1!$H$2:$H$503,H5,Página1!$G$2:$G$503) -> 14259.327 | J5: =COUNTIF(Página1!$H$2:$H$503,H5) -> 5 | K5: Até | L5: 20000 | M5: =COUNTIFS(Página1!$E$2:$E$503,"<="&L5,Página1!$E$2:$E$503,">"&L4) -> 17 | N5: =SUMIFS(Página1!$E$2:$E$503,Página1!$E$2:E$503,"<="&L5,Página1!$E$2:$E$503,">"&L4) -> 288274 | O5: =N5/Página1!$E$504 -> 0.025314442 | P5: =M5/497 -> 0.034205231
A6: 182 | B6: Alecrim | C6: 316.394 | D6: 0.1123 | H6: Campanha Ocidental | I6: =SUMIF(Página1!$H$2:$H$503,H6,Página1!$G$2:$G$503) -> 31107.195 | J6: =COUNTIF(Página1!$H$2:$H$503,H6) -> 10 | K6: Até | L6: 25000 | M6: =COUNTIFS(Página1!$E$2:$E$503,"<="&L6,Página1!$E$2:$E$503,">"&L5) -> 20 | N6: =SUMIFS(Página1!$E$2:$E$503,Página1!$E$2:E$503,"<="&L6,Página1!$E$2:$E$503,">"&L5) -> 451057 | O6: =N6/Página1!$E$504 -> 0.039609039 | P6: =M6/497 -> 0.040241449
A7: 1 | B7: Alegrete | C7: 7800.163 | D7: 2.7689 | H7: Carazinho | I7: =SUMIF(Página1!$H$2:$H$503,H7,Página1!$G$2:$G$503) -> 5188.101 | J7: =COUNTIF(Página1!$H$2:$H$503,H7) -> 18 | K7: Até | L7: 30000 | M7: =COUNTIFS(Página1!$E$2:$E$503,"<="&L7,Página1!$E$2:$E$503,">"&L6) -> 16 | N7: =SUMIFS(Página1!$E$2:$E$503,Página1!$E$2:E$503,"<="&L7,Página1!$E$2:$E$503,">"&L6) -> 438488 | O7: =N7/Página1!$E$504 -> 0.038505307 | P7: =M7/497 -> 0.032193159
A8: 311 | B8: Alegria | C8: 172.794 | D8: 0.0613 | H8: Caxias do Sul | I8: =SUMIF(Página1!$H$2:$H$503,H8,Página1!$G$2:$G$503) -> 4967.35 | J8: =COUNTIF(Página1!$H$2:$H$503,H8) -> 19 | K8: Até | L8: 40000 | M8: =COUNTIFS(Página1!$E$2:$E$503,"<="&L8,Página1!$E$2:$E$503,">"&L7) -> 19 | N8: =SUMIFS(Página1!$E$2:$E$503,Página1!$E$2:E$503,"<="&L8,Página1!$E$2:$E$503,">"&L7) -> 662629 | O8: =N8/Página1!$E$504 -> 0.058187985 | P8: =M8/497 -> 0.038229376
A9: 220 | B9: Almirante Tamandaré do Sul | C9: 265.327 | D9: 0.0942 | H9: Cerro Largo | I9: =SUMIF(Página1!$H$2:$H$503,H9,Página1!$G$2:$G$503) -> 2253.722 | J9: =COUNTIF(Página1!$H$2:$H$503,H9) -> 11 | K9: Até | L9: 50000 | M9: =COUNTIFS(Página1!$E$2:$E$503,"<="&L9,Página1!$E$2:$E$503,">"&L8) -> 9 | N9: =SUMIFS(Página1!$E$2:$E$503,Página1!$E$2:E$503,"<="&L9,Página1!$E$2:$E$503,">"&L8) -> 396795 | O9: =N9/Página1!$E$504 -> 0.034844085 | P9: =M9/497 -> 0.018108652
A10: 178 | B10: Alpestre | C10: 325.979 | D10: 0.1157 | H10: Cruz Alta | I10: =SUMIF(Página1!$H$2:$H$503,H10,Página1!$G$2:$G$503) -> 8453.302 | J10: =COUNTIF(Página1!$H$2:$H$503,H10) -> 14 | K10: Até | L10: 60000 | M10: =COUNTIFS(Página1!$E$2:$E$503,"<="&L10,Página1!$E$2:$E$503,">"&L9) -> 6 | N10: =SUMIFS(Página1!$E$2:$E$503,Página1!$E$2:E$503,"<="&L10,Página1!$E$2:$E$503,">"&L9) -> 326569 | O10: =N10/Página1!$E$504 -> 0.028677272 | P10: =M10/497 -> 0.012072435
A11: 387 | B11: Alto Alegre | C11: 115.335 | D11: 0.0409 | H11: Erechim | I11: =SUMIF(Página1!$H$2:$H$503,H11,Página1!$G$2:$G$503) -> 5724.88 | J11: =COUNTIF(Página1!$H$2:$H$503,H11) -> 30 | K11: Até | L11: 70000 | M11: =COUNTIFS(Página1!$E$2:$E$503,"<="&L11,Página1!$E$2:$E$503,">"&L10) -> 8 | N11: =SUMIFS(Página1!$E$2:$E$503,Página1!$E$2:E$503,"<="&L11,Página1!$E$2:$E$503,">"&L10) -> 509251 | O11: =N11/Página1!$E$504 -> 0.044719276 | P11: =M11/497 -> 0.016096579
A12: 450 | B12: Alto Feliz | C12: 78.846 | D12: 0.028 | H12: Frederico Westphalen | I12: =SUMIF(Página1!$H$2:$H$503,H12,Página1!$G$2:$G$503) -> 5147.84 | J12: =COUNTIF(Página1!$H$2:$H$503,H12) -> 27 | K12: Até | L12: 80000 | M12: =COUNTIFS(Página1!$E$2:$E$503,"<="&L12,Página1!$E$2:$E$503,">"&L11) -> 6 | N12: =SUMIFS(Página1!$E$2:$E$503,Página1!$E$2:E$503,"<="&L12,Página1!$E$2:$E$503,">"&L11) -> 445348 | O12: =N12/Página1!$E$504 -> 0.03910771 | P12: =M12/497 -> 0.012072435
A13: 464 | B13: Alvorada | C13: 71.648 | D13: 0.0254 | H13: Gramado-Canela | I13: =SUMIF(Página1!$H$2:$H$503,H13,Página1!$G$2:$G$503) -> 2761.816 | J13: =COUNTIF(Página1!$H$2:$H$503,H13) -> 15 | K13: Até | L13: 90000 | M13: =COUNTIFS(Página1!$E$2:$E$503,"<="&L13,Página1!$E$2:$E$503,">"&L12) -> 5 | N13: =SUMIFS(Página1!$E$2:$E$503,Página1!$E$2:E$503,"<="&L13,Página1!$E$2:$E$503,">"&L12) -> 414626 | O13: =N13/Página1!$E$504 -> 0.036409893 | P13: =M13/497 -> 0.010060362
A14: 123 | B14: Amaral Ferrador | C14: 505.983 | D14: 0.1796 | H14: Guaporé | I14: =SUMIF(Página1!$H$2:$H$503,H14,Página1!$G$2:$G$503) -> 3591.154 | J14: =COUNTIF(Página1!$H$2:$H$503,H14) -> 21 | K14: Até | L14: 100000 | M14: =COUNTIFS(Página1!$E$2:$E$503,"<="&L14,Página1!$E$2:$E$503,">"&L13) -> 1 | N14: =SUMIFS(Página1!$E$2:$E$503,Página1!$E$2:E$503,"<="&L14,Página1!$E$2:$E$503,">"&L13) -> 98143 | O14: =N14/Página1!$E$504 -> 0.0086183119 | P14: =M14/497 -> 0.0020120724
... A17: 242 | B17: Anta Gorda | C17: 242.26 | D17: 0.086 | H17: Lajeado Estrela | I17: =SUMIF(Página1!$H$2:$H$503,H17,Página1!$G$2:$G$503) -> 286.5 | J17: =COUNTIF(Página1!$H$2:$H$503,H17) -> 2 | K17: Até | L17: 350000 | M17: =COUNTIFS(Página1!$E$2:$E$503,"<="&L17,Página1!$E$2:$E$503,">"&L16) -> 4 | N17: =SUMIFS(Página1!$E$2:$E$503,Página1!$E$2:E$503,"<="&L17,Página1!$E$2:$E$503,">"&L16) -> 1161808 | O17: =N17/Página1!$E$504 -> 0.1020228 | P17: =M17/497 -> 0.0080482897
A18: 167 | B18: Antônio Prado | C18: 348.191 | D18: 0.1236 | H18: Lajeado-Estrela | I18: =SUMIF(Página1!$H$2:$H$503,H18,Página1!$G$2:$G$503) -> 3768.721 | J18: =COUNTIF(Página1!$H$2:$H$503,H18) -> 29 | K18: Acima | L18: 350000 | M18: =COUNTIF(Página1!$E$2:$E$503,">="&L18) -> 3 | N18: =SUMIF(Página1!$E$2:$E$503,">="&L18) -> 2349006 | O18: =N18/Página1!$E$504 -> 0.20627519 | P18: =M18/497 -> 0.0060362173
A19: 116 | B19: Arambaré | C19: 518.193 | D19: 0.1839 | H19: Litoral Lagunar | I19: =SUMIF(Página1!$H$2:$H$503,H19,Página1!$G$2:$G$503) -> 9179.269 | J19: =COUNTIF(Página1!$H$2:$H$503,H19) -> 4
A20: 493 | B20: Araricá | C20: 35.296 | D20: 0.0125 | H20: Montenegro | I20: =SUMIF(Página1!$H$2:$H$503,H20,Página1!$G$2:$G$503) -> 2081.575 | J20: =COUNTIF(Página1!$H$2:$H$503,H20) -> 21
A21: 168 | B21: Aratiba | C21: 342.279 | D21: 0.1215 | H21: Não-Me-Toque | I21: =SUMIF(Página1!$H$2:$H$503,H21,Página1!$G$2:$G$503) -> 1495.069 | J21: =COUNTIF(Página1!$H$2:$H$503,H21) -> 7
A22: 328 | B22: Arroio do Meio | C22: 157.58 | D22: 0.0559 | H22: Osório | I22: =SUMIF(Página1!$H$2:$H$503,H22,Página1!$G$2:$G$503) -> 8766.414 | J22: =COUNTIF(Página1!$H$2:$H$503,H22) -> 23
A23: 374 | B23: Arroio do Padre | C23: 124.693 | D23: 0.0443 | H23: Passo Fundo | I23: =SUMIF(Página1!$H$2:$H$503,H23,Página1!$G$2:$G$503) -> 7063.617 | J23: =COUNTIF(Página1!$H$2:$H$503,H23) -> 26
A24: 384 | B24: Arroio do Sal | C24: 119.163 | D24: 0.0423 | H24: Pelotas | I24: =SUMIF(Página1!$H$2:$H$503,H24,Página1!$G$2:$G$503) -> 10316.277 | J24: =COUNTIF(Página1!$H$2:$H$503,H24) -> 10
A25: 183 | B25: Arroio do Tigre | C25: 315.132 | D25: 0.1119 | H25: Porto Alegre | I25: =SUMIF(Página1!$H$2:$H$503,H25,Página1!$G$2:$G$503) -> 5588.014 | J25: =COUNTIF(Página1!$H$2:$H$503,H25) -> 22
A26: 143 | B26: Arroio dos Ratos | C26: 425.791 | D26: 0.1511 | H26: Restinga Seca | I26: =SUMIF(Página1!$H$2:$H$503,H26,Página1!$G$2:$G$503) -> 3000.93 | J26: =COUNTIF(Página1!$H$2:$H$503,H26) -> 9
A27: 21 | B27: Arroio Grande | C27: 2508.545 | D27: 0.8905 | H27: Sananduva | I27: =SUMIF(Página1!$H$2:$H$503,H27,Página1!$G$2:$G$503) -> 3065.646 | J27: =COUNTIF(Página1!$H$2:$H$503,H27) -> 11
A28: 214 | B28: Arvorezinha | C28: 270.241 | D28: 0.0959 | H28: Santa Cruz do Sul | I28: =SUMIF(Página1!$H$2:$H$503,H28,Página1!$G$2:$G$503) -> 5475.222 | J28: =COUNTIF(Página1!$H$2:$H$503,H28) -> 16
A29: 166 | B29: Augusto Pestana | C29: 348.33 | D29: 0.1236 | H29: Santa Maria | I29: =SUMIF(Página1!$H$2:$H$503,H29,Página1!$G$2:$G$503) -> 11735.54 | J29: =COUNTIF(Página1!$H$2:$H$503,H29) -> 13
A30: 329 | B30: Áurea | C30: 156.727 | D30: 0.0556 | H30: Santa Rosa | I30: =SUMIF(Página1!$H$2:$H$503,H30,Página1!$G$2:$G$503) -> 3456.055 | J30: =COUNTIF(Página1!$H$2:$H$503,H30) -> 13
... A37: 61 | B37: Barra do Quaraí | C37: 1055.937 | D37: 0.3748 | H37: Vacaria | I37: =SUMIF(Página1!$H$2:$H$503,H37,Página1!$G$2:$G$503) -> 17238.692 | J37: =COUNTIF(Página1!$H$2:$H$503,H37) -> 14
A38: 87 | B38: Barra do Ribeiro | C38: 729.316 | D38: 0.2589
A39: 342 | B39: Barra do Rio Azul | C39: 146.995 | D39: 0.0522
A40: 480 | B40: Barra Funda | C40: 60.437 | D40: 0.0215
A41: 117 | B41: Barracão | C41: 515.469 | D41: 0.183
A42: 99 | B42: Barros Cassal | C42: 647.994 | D42: 0.23
A43: 360 | B43: Benjamin Constant do Sul | C43: 132.351 | D43: 0.047
A44: 212 | B44: Bento Gonçalves | C44: 273.576 | D44: 0.0971
A45: 287 | B45: Boa Vista das Missões | C45: 196.064 | D45: 0.0696
A46: 398 | B46: Boa Vista do Buricá | C46: 109.557 | D46: 0.0389
A47: 88 | B47: Boa Vista do Cadeado | C47: 701.315 | D47: 0.249
A48: 125 | B48: Boa Vista do Incra | C48: 504.114 | D48: 0.1789
...

Sheet Página4

Sheet Página5
